<?xml version="1.0" ?>
<robot name="scoopy" xmlns:xacro="http://www.ros.org/wiki/xacro">

<xacro:include filename="$(find scoopy_description)/urdf/materials.xacro" />
<xacro:include filename="$(find scoopy_description)/urdf/scoopy.trans" />
<xacro:include filename="$(find scoopy_description)/urdf/scoopy.gazebo" />
<link name="base_link">
  <inertial>
    <origin rpy="0 0 0" xyz="-1.3881137481563912e-16 1.3881137481563912e-16 0.11331032359466349"/>
    <mass value="35.55911503662972"/>
    <inertia ixx="0.662233" ixy="0.0" ixz="0.0" iyy="0.560224" iyz="0.0" izz="0.990291"/>
  </inertial>
  <visual>
    <origin rpy="0 0 0" xyz="0 0 0"/>
    <geometry>
      <mesh filename="package://scoopy_description/meshes/base_link.stl" scale="0.001 0.001 0.001"/>
    </geometry>
    <material name="silver"/>
  </visual>
  <collision>
    <origin rpy="0 0 0" xyz="0 0 0"/>
    <geometry>
      <mesh filename="package://scoopy_description/meshes/base_link.stl" scale="0.001 0.001 0.001"/>
    </geometry>
  </collision>
</link>

<link name="post_1">
  <inertial>
    <origin rpy="0 0 0" xyz="6.693613260518336e-17 -0.07500000000000001 0.6000000000000001"/>
    <mass value="2.934899999999997"/>
    <inertia ixx="0.356822" ixy="0.0" ixz="-0.0" iyy="0.358514" iyz="-0.0" izz="0.002"/>
  </inertial>
  <visual>
    <origin rpy="0 0 0" xyz="0.0 -0.0 -0.21"/>
    <geometry>
      <mesh filename="package://scoopy_description/meshes/post_1.stl" scale="0.001 0.001 0.001"/>
    </geometry>
    <material name="silver"/>
  </visual>
  <collision>
    <origin rpy="0 0 0" xyz="0.0 -0.0 -0.21"/>
    <geometry>
      <mesh filename="package://scoopy_description/meshes/post_1.stl" scale="0.001 0.001 0.001"/>
    </geometry>
  </collision>
</link>

<link name="blw_1">
  <inertial>
    <origin rpy="0 0 0" xyz="2.2386537068541656e-12 0.02499999962857044 3.01187547124826e-12"/>
    <mass value="0.39514309079192295"/>
    <inertia ixx="0.000315" ixy="0.0" ixz="0.0" iyy="0.00047" iyz="-0.0" izz="0.000315"/>
  </inertial>
  <visual>
    <origin rpy="0 0 0" xyz="0.15 -0.175 -0.05"/>
    <geometry>
      <mesh filename="package://scoopy_description/meshes/blw_1.stl" scale="0.001 0.001 0.001"/>
    </geometry>
    <material name="silver"/>
  </visual>
  <collision>
    <origin rpy="0 0 0" xyz="0.15 -0.175 -0.05"/>
    <geometry>
      <mesh filename="package://scoopy_description/meshes/blw_1.stl" scale="0.001 0.001 0.001"/>
    </geometry>
  </collision>
</link>

<link name="flw_1">
  <inertial>
    <origin rpy="0 0 0" xyz="-2.238764729156628e-12 0.024999999628570274 3.011861593460452e-12"/>
    <mass value="0.39514309079192345"/>
    <inertia ixx="0.000315" ixy="-0.0" ixz="-0.0" iyy="0.00047" iyz="-0.0" izz="0.000315"/>
  </inertial>
  <visual>
    <origin rpy="0 0 0" xyz="-0.15 -0.175 -0.05"/>
    <geometry>
      <mesh filename="package://scoopy_description/meshes/flw_1.stl" scale="0.001 0.001 0.001"/>
    </geometry>
    <material name="silver"/>
  </visual>
  <collision>
    <origin rpy="0 0 0" xyz="-0.15 -0.175 -0.05"/>
    <geometry>
      <mesh filename="package://scoopy_description/meshes/flw_1.stl" scale="0.001 0.001 0.001"/>
    </geometry>
  </collision>
</link>

<link name="brw_1">
  <inertial>
    <origin rpy="0 0 0" xyz="-2.1991575227531257e-12 -0.02500000015165485 3.1027957980711562e-12"/>
    <mass value="0.39514304955144675"/>
    <inertia ixx="0.000315" ixy="-0.0" ixz="-0.0" iyy="0.00047" iyz="0.0" izz="0.000315"/>
  </inertial>
  <visual>
    <origin rpy="0 0 0" xyz="0.15 0.175 -0.05"/>
    <geometry>
      <mesh filename="package://scoopy_description/meshes/brw_1.stl" scale="0.001 0.001 0.001"/>
    </geometry>
    <material name="silver"/>
  </visual>
  <collision>
    <origin rpy="0 0 0" xyz="0.15 0.175 -0.05"/>
    <geometry>
      <mesh filename="package://scoopy_description/meshes/brw_1.stl" scale="0.001 0.001 0.001"/>
    </geometry>
  </collision>
</link>

<link name="frw_1">
  <inertial>
    <origin rpy="0 0 0" xyz="2.1991020116018944e-12 -0.025000000151654544 3.1027680424955406e-12"/>
    <mass value="0.39514304955144725"/>
    <inertia ixx="0.000315" ixy="0.0" ixz="0.0" iyy="0.00047" iyz="0.0" izz="0.000315"/>
  </inertial>
  <visual>
    <origin rpy="0 0 0" xyz="-0.15 0.175 -0.05"/>
    <geometry>
      <mesh filename="package://scoopy_description/meshes/frw_1.stl" scale="0.001 0.001 0.001"/>
    </geometry>
    <material name="silver"/>
  </visual>
  <collision>
    <origin rpy="0 0 0" xyz="-0.15 0.175 -0.05"/>
    <geometry>
      <mesh filename="package://scoopy_description/meshes/frw_1.stl" scale="0.001 0.001 0.001"/>
    </geometry>
  </collision>
</link>

<link name="teslecope_outer_1">
  <inertial>
    <origin rpy="0 0 0" xyz="0.00486686631843313 0.06003062430127173 0.03525240226031212"/>
    <mass value="0.7345811625725633"/>
    <inertia ixx="0.002063" ixy="0.000488" ixz="-2.1e-05" iyy="0.009276" iyz="9e-06" izz="0.010304"/>
  </inertial>
  <visual>
    <origin rpy="0 0 0" xyz="-0.0 0.085 -0.21"/>
    <geometry>
      <mesh filename="package://scoopy_description/meshes/teslecope_outer_1.stl" scale="0.001 0.001 0.001"/>
    </geometry>
    <material name="silver"/>
  </visual>
  <collision>
    <origin rpy="0 0 0" xyz="-0.0 0.085 -0.21"/>
    <geometry>
      <mesh filename="package://scoopy_description/meshes/teslecope_outer_1.stl" scale="0.001 0.001 0.001"/>
    </geometry>
  </collision>
</link>

<link name="telescope_mid_1">
  <inertial>
    <origin rpy="0 0 0" xyz="0.19750000000000004 3.890818109301545e-17 0.03"/>
    <mass value="0.4336138633043531"/>
    <inertia ixx="0.000423" ixy="0.0" ixz="0.0" iyy="0.005849" iyz="0.0" izz="0.005849"/>
  </inertial>
  <visual>
    <origin rpy="0 0 0" xyz="0.195 0.0 -0.215"/>
    <geometry>
      <mesh filename="package://scoopy_description/meshes/telescope_mid_1.stl" scale="0.001 0.001 0.001"/>
    </geometry>
    <material name="silver"/>
  </visual>
  <collision>
    <origin rpy="0 0 0" xyz="0.195 0.0 -0.215"/>
    <geometry>
      <mesh filename="package://scoopy_description/meshes/telescope_mid_1.stl" scale="0.001 0.001 0.001"/>
    </geometry>
  </collision>
</link>

<link name="telescope_inner_1">
  <inertial>
    <origin rpy="0 0 0" xyz="0.28166216034704594 -2.5972465324787718e-08 0.023861399579124587"/>
    <mass value="0.566702462514632"/>
    <inertia ixx="0.000504" ixy="0.0" ixz="0.000112" iyy="0.014419" iyz="-0.0" izz="0.014397"/>
  </inertial>
  <visual>
    <origin rpy="0 0 0" xyz="0.195 0.0 -0.22"/>
    <geometry>
      <mesh filename="package://scoopy_description/meshes/telescope_inner_1.stl" scale="0.001 0.001 0.001"/>
    </geometry>
    <material name="silver"/>
  </visual>
  <collision>
    <origin rpy="0 0 0" xyz="0.195 0.0 -0.22"/>
    <geometry>
      <mesh filename="package://scoopy_description/meshes/telescope_inner_1.stl" scale="0.001 0.001 0.001"/>
    </geometry>
  </collision>
</link>

<link name="scooper_main_1">
  <inertial>
    <origin rpy="0 0 0" xyz="0.08092508837262535 -1.0539086043948146e-08 -0.12225840583681827"/>
    <mass value="0.7354620730651008"/>
    <inertia ixx="0.004063" ixy="-0.0" ixz="0.000612" iyy="0.007462" iyz="-0.0" izz="0.006171"/>
  </inertial>
  <visual>
    <origin rpy="0 0 0" xyz="-0.26 -0.0 -0.2"/>
    <geometry>
      <mesh filename="package://scoopy_description/meshes/scooper_main_1.stl" scale="0.001 0.001 0.001"/>
    </geometry>
    <material name="silver"/>
  </visual>
  <collision>
    <origin rpy="0 0 0" xyz="-0.26 -0.0 -0.2"/>
    <geometry>
      <mesh filename="package://scoopy_description/meshes/scooper_main_1.stl" scale="0.001 0.001 0.001"/>
    </geometry>
  </collision>
</link>

<link name="vacuum_1">
  <inertial>
    <origin rpy="0 0 0" xyz="1.316169395693123e-13 -2.1186220889083034e-15 0.002499999999999988"/>
    <mass value="0.005723589115758862"/>
    <inertia ixx="1e-06" ixy="0.0" ixz="0.0" iyy="1e-06" iyz="0.0" izz="1e-06"/>
  </inertial>
  <visual>
    <origin rpy="0 0 0" xyz="-0.26 0.0 -0.0"/>
    <geometry>
      <mesh filename="package://scoopy_description/meshes/vacuum_1.stl" scale="0.001 0.001 0.001"/>
    </geometry>
    <material name="silver"/>
  </visual>
  
  <collision>
    <origin rpy="0 0 0" xyz="-0.26 0.0 -0.0"/>
    <geometry>
      <mesh filename="package://scoopy_description/meshes/vacuum_1.stl" scale="0.001 0.001 0.001"/>
    </geometry>
  </collision>
  
</link>

<link name="sprayer_1">
  <inertial>
    <origin rpy="0 0 0" xyz="3.219646771412954e-15 -2.0719939435983563e-15 0.002499999999999988"/>
    <mass value="0.000936587309851457"/>
    <inertia ixx="0.0" ixy="-0.0" ixz="0.0" iyy="0.0" iyz="0.0" izz="0.0"/>
  </inertial>
  <visual>
    <origin rpy="0 0 0" xyz="-0.26 0.0 -0.0"/>
    <geometry>
      <mesh filename="package://scoopy_description/meshes/sprayer_1.stl" scale="0.001 0.001 0.001"/>
    </geometry>
    <material name="silver"/>
  </visual>
  <collision>
    <origin rpy="0 0 0" xyz="-0.26 0.0 -0.0"/>
    <geometry>
      <mesh filename="package://scoopy_description/meshes/sprayer_1.stl" scale="0.001 0.001 0.001"/>
    </geometry>
  </collision>
</link>

<link name="lid_1">
  <inertial>
    <origin rpy="0 0 0" xyz="0.0023329144952143888 0.050000000000000065 -0.07605260689634684"/>
    <mass value="0.08879847467817195"/>
    <inertia ixx="0.00028" ixy="0.0" ixz="1e-06" iyy="0.000206" iyz="-0.0" izz="7.4e-05"/>
  </inertial>
  <visual>
    <origin rpy="0 0 0" xyz="-0.48 0.05 -0.165"/>
    <geometry>
      <mesh filename="package://scoopy_description/meshes/lid_1.stl" scale="0.001 0.001 0.001"/>
    </geometry>
    <material name="silver"/>
  </visual>
  <collision>
    <origin rpy="0 0 0" xyz="-0.48 0.05 -0.165"/>
    <geometry>
      <mesh filename="package://scoopy_description/meshes/lid_1.stl" scale="0.001 0.001 0.001"/>
    </geometry>
  </collision>
</link>

<link name="camera_rotator_1">
  <inertial>
    <origin rpy="0 0 0" xyz="3.911142606330705e-15 0.017785128226742025 -0.03706116149026073"/>
    <mass value="0.0194038742394048"/>
    <inertia ixx="2.2e-05" ixy="-0.0" ixz="0.0" iyy="2.1e-05" iyz="3e-06" izz="3e-06"/>
  </inertial>
  <visual>
    <origin rpy="0 0 0" xyz="-0.0 -0.085 -1.41"/>
    <geometry>
      <mesh filename="package://scoopy_description/meshes/camera_rotator_1.stl" scale="0.001 0.001 0.001"/>
    </geometry>
    <material name="silver"/>
  </visual>
  <collision>
    <origin rpy="0 0 0" xyz="-0.0 -0.085 -1.41"/>
    <geometry>
      <mesh filename="package://scoopy_description/meshes/camera_rotator_1.stl" scale="0.001 0.001 0.001"/>
    </geometry>
  </collision>
</link>

<link name="realsense_1">
  <inertial>
    <origin rpy="0 0 0" xyz="0.0031990044720235484 -0.020000113475681897 -4.398305875064068e-07"/>
    <mass value="0.29079830925727457"/>
    <inertia ixx="0.000399" ixy="-0.0" ixz="0.0" iyy="0.000437" iyz="-0.0" izz="0.000112"/>
  </inertial>
  <visual>
    <origin rpy="0 0 0" xyz="-0.0 -0.105 -1.325"/>
    <geometry>
      <mesh filename="package://scoopy_description/meshes/realsense_1.stl" scale="0.001 0.001 0.001"/>
    </geometry>
    <material name="silver"/>
  </visual>
  <collision>
    <origin rpy="0 0 0" xyz="-0.0 -0.105 -1.325"/>
    <geometry>
      <mesh filename="package://scoopy_description/meshes/realsense_1.stl" scale="0.001 0.001 0.001"/>
    </geometry>
  </collision>
</link>

<link name="hat_1">
  <inertial>
    <origin rpy="0 0 0" xyz="3.677005365676489e-15 0.09525941907785543 0.014973792021365284"/>
    <mass value="0.18773692557600277"/>
    <inertia ixx="0.000906" ixy="-0.0" ixz="0.0" iyy="0.000223" iyz="0.0" izz="0.001074"/>
  </inertial>
  <visual>
    <origin rpy="0 0 0" xyz="-0.0 0.085 -1.41"/>
    <geometry>
      <mesh filename="package://scoopy_description/meshes/hat_1.stl" scale="0.001 0.001 0.001"/>
    </geometry>
    <material name="silver"/>
  </visual>
  <collision>
    <origin rpy="0 0 0" xyz="-0.0 0.085 -1.41"/>
    <geometry>
      <mesh filename="package://scoopy_description/meshes/hat_1.stl" scale="0.001 0.001 0.001"/>
    </geometry>
  </collision>
</link>

<link name="lidar_1">
  <inertial>
    <origin rpy="0 0 0" xyz="2.7755575615628914e-17 -1.249000902703301e-16 0.009717213114754153"/>
    <mass value="0.08463974207546501"/>
    <inertia ixx="3e-05" ixy="-0.0" ixz="0.0" iyy="3e-05" iyz="-0.0" izz="5.4e-05"/>
  </inertial>
  <visual>
    <origin rpy="0 0 0" xyz="-0.12 0.075 -0.285"/>
    <geometry>
      <mesh filename="package://scoopy_description/meshes/lidar_1.stl" scale="0.001 0.001 0.001"/>
    </geometry>
    <material name="silver"/>
  </visual>
  <collision>
    <origin rpy="0 0 0" xyz="-0.12 0.075 -0.285"/>
    <geometry>
      <mesh filename="package://scoopy_description/meshes/lidar_1.stl" scale="0.001 0.001 0.001"/>
    </geometry>
  </collision>
</link>

<link name="camera_1">
  <inertial>
    <origin rpy="0 0 0" xyz="-0.0004999999999967808 -7.84200703550174e-13 -4.2567708755103517e-07"/>
    <mass value="0.00018731746197030215"/>
    <inertia ixx="0.0" ixy="0.0" ixz="-0.0" iyy="0.0" iyz="-0.0" izz="0.0"/>
  </inertial>
  <visual>
    <origin rpy="0 0 0" xyz="-0.48 -0.0 -0.083102"/>
    <geometry>
      <mesh filename="package://scoopy_description/meshes/camera_1.stl" scale="0.001 0.001 0.001"/>
    </geometry>
    <material name="silver"/>
  </visual>
  <collision>
    <origin rpy="0 0 0" xyz="-0.48 -0.0 -0.083102"/>
    <geometry>
      <mesh filename="package://scoopy_description/meshes/camera_1.stl" scale="0.001 0.001 0.001"/>
    </geometry>
  </collision>
</link>

<joint name="post_rigid" type="fixed">
  <origin rpy="0 0 0" xyz="0.0 0.0 0.21"/>
  <parent link="base_link"/>
  <child link="post_1"/>
</joint>

<joint name="blw_revolute" type="continuous">
  <origin rpy="0 0 0" xyz="-0.15 0.175 0.05"/>
  <parent link="base_link"/>
  <child link="blw_1"/>
  <axis xyz="0.0 1.0 0.0"/>
</joint>

<joint name="flw_revolute" type="continuous">
  <origin rpy="0 0 0" xyz="0.15 0.175 0.05"/>
  <parent link="base_link"/>
  <child link="flw_1"/>
  <axis xyz="0.0 1.0 0.0"/>
</joint>

<joint name="brw_revolute" type="continuous">
  <origin rpy="0 0 0" xyz="-0.15 -0.175 0.05"/>
  <parent link="base_link"/>
  <child link="brw_1"/>
  <axis xyz="-0.0 -1.0 0.0"/>
</joint>

<joint name="frw_revolute" type="continuous">
  <origin rpy="0 0 0" xyz="0.15 -0.175 0.05"/>
  <parent link="base_link"/>
  <child link="frw_1"/>
  <axis xyz="-0.0 -1.0 0.0"/>
</joint>

<joint name="post_slider" type="prismatic">
  <origin rpy="0 0 0" xyz="0.0 -0.085 0.0"/>
  <parent link="post_1"/>
  <child link="teslecope_outer_1"/>
  <axis xyz="0.0 0.0 1.0"/>
  <limit effort="200" lower="0.0" upper="1.12" velocity="1000"/>
</joint>

<joint name="outer_mid_slider" type="prismatic">
  <origin rpy="0 0 0" xyz="-0.195 0.085 0.005"/>
  <parent link="teslecope_outer_1"/>
  <child link="telescope_mid_1"/>
  <axis xyz="1.0 0.0 0.0"/>
  <limit effort="100" lower="0.0" upper="0.3" velocity="100"/>
</joint>

<joint name="mid_inner_slider" type="prismatic">
  <origin rpy="0 0 0" xyz="0.0 0.0 0.005"/>
  <parent link="telescope_mid_1"/>
  <child link="telescope_inner_1"/>
  <axis xyz="1.0 0.0 0.0"/>
  <limit effort="100" lower="0.0" upper="0.3" velocity="100"/>
</joint>

<joint name="toolhead_revolute" type="revolute">
  <origin rpy="0 0 0" xyz="0.455 0.0 -0.02"/>
  <parent link="telescope_inner_1"/>
  <child link="scooper_main_1"/>
  <axis xyz="0.0 0.0 -1.0"/>
  <limit effort="20" lower="-1.570796" upper="1.570796" velocity="20"/>
</joint>

<joint name="vacuum_rigid" type="fixed">
  <origin rpy="0 0 0" xyz="0.0 -0.0 -0.2"/>
  <parent link="scooper_main_1"/>
  <child link="vacuum_1"/>
</joint>

<joint name="sprayer_rigid" type="fixed">
  <origin rpy="0 0 0" xyz="0.0 -0.0 -0.2"/>
  <parent link="scooper_main_1"/>
  <child link="sprayer_1"/>
</joint>

<joint name="lid_revolute" type="continuous">
  <origin rpy="0 0 0" xyz="0.22 -0.05 -0.035"/>
  <parent link="scooper_main_1"/>
  <child link="lid_1"/>
  <axis xyz="0.0 1.0 0.0"/>
</joint>

<joint name="camera_pan" type="continuous">
  <origin rpy="0 0 0" xyz="0.0 0.17 0.0"/>
  <parent link="hat_1"/>
  <child link="camera_rotator_1"/>
  <axis xyz="0.0 0.0 -1.0"/>
</joint>

<joint name="camera_tilt" type="continuous">
  <origin rpy="0 1 0" xyz="0.0 0.02 -0.085"/>
  <parent link="camera_rotator_1"/>
  <child link="realsense_1"/>
  <axis xyz="0.0 -1.0 0.0"/>
</joint>

<joint name="hat_rigid" type="fixed">
  <origin rpy="0 0 0" xyz="0.0 -0.085 1.2"/>
  <parent link="post_1"/>
  <child link="hat_1"/>
</joint>

<joint name="lidar" type="fixed">
  <origin rpy="0 0 0" xyz="0.12 0.01 0.075"/>
  <parent link="teslecope_outer_1"/>
  <child link="lidar_1"/>
</joint>

<joint name="Rigid28" type="fixed">
  <origin rpy="0 0 0" xyz="0.0 0.05 -0.081898"/>
  <parent link="lid_1"/>
  <child link="camera_1"/>
</joint>

</robot>
